test_1 (__main__.Prodnik) ... ok
test_2 (__main__.Prodnik) ... FAIL
test_3 (__main__.Prodnik) ... FAIL

======================================================================
FAIL: test_2 (__main__.Prodnik)
----------------------------------------------------------------------
Traceback (most recent call last):
  File "/Users/arsenijturlapov/work/Programming/Python/telegram_bot_1/tests/probnik.py", line 19, in test_2
    self.assertEqual(1, 3)
AssertionError: 1 != 3

======================================================================
FAIL: test_3 (__main__.Prodnik)
----------------------------------------------------------------------
Traceback (most recent call last):
  File "/Users/arsenijturlapov/work/Programming/Python/telegram_bot_1/tests/probnik.py", line 22, in test_3
    self.assertEqual(1, 2)
AssertionError: 1 != 2

----------------------------------------------------------------------
Ran 3 tests in 0.000s

FAILED (failures=2)
